#VRML_SIM R2020b utf8
WorldInfo {
  basicTimeStep 1
}
Viewpoint {
  orientation -0.3601076496003352 -0.3119994270094387 -0.8791921509232802 4.615100807144303
  position 3.0891163430355064 0.6388799507424145 3.3062256188566956
}
TexturedBackground {
}
TexturedBackgroundLight {
}
RectangleArena {
  translation 0 0.83 -5.08212e-17
  rotation 1 0 0 1.5707963267948966
  floorSize 3 3
  wallHeight 1
}
DEF arrow Solid {
  translation 0.105 0 0.4
  rotation 0 1 0 3.14159
  children [
    Solid {
      translation 0 -0.075 -0.01
      children [
        Shape {
          geometry Box {
            size 0.01 0.05 0.01
          }
        }
      ]
      immersionProperties [
        ImmersionProperties {
          fluidName "fluid"
          referenceArea "xyz-projection"
          dragForceCoefficients 2 2 2
        }
      ]
      boundingObject Shape {
        geometry Box {
          size 0.01 0.05 0.01
        }
      }
      physics Physics {
        density 100
      }
    }
    Solid {
      translation 0 -0.075 0.01
      children [
        Shape {
          geometry Box {
            size 0.01 0.05 0.01
          }
        }
      ]
      name "solid(1)"
      immersionProperties [
        ImmersionProperties {
          fluidName "fluid"
          referenceArea "xyz-projection"
          dragForceCoefficients 2 2 2
        }
      ]
      boundingObject Shape {
        geometry Box {
          size 0.01 0.05 0.01
        }
      }
      physics Physics {
        density 100
      }
    }
    Solid {
      translation 0.01 -0.075 0
      children [
        Shape {
          geometry Box {
            size 0.01 0.05 0.01
          }
        }
      ]
      name "solid(2)"
      immersionProperties [
        ImmersionProperties {
          fluidName "fluid"
          referenceArea "xyz-projection"
          dragForceCoefficients 2 2 2
        }
      ]
      boundingObject Shape {
        geometry Box {
          size 0.01 0.05 0.01
        }
      }
      physics Physics {
        density 100
      }
    }
    Solid {
      translation -0.01 -0.075 0
      children [
        Shape {
          geometry Box {
            size 0.01 0.05 0.01
          }
        }
      ]
      name "solid(3)"
      immersionProperties [
        ImmersionProperties {
          fluidName "fluid"
          referenceArea "xyz-projection"
          dragForceCoefficients 2 2 2
        }
      ]
      boundingObject Shape {
        geometry Box {
          size 0.01 0.05 0.01
        }
      }
      physics Physics {
        density 100
      }
    }
    Connector {
      translation 0.035 0 0
      model "arm_cnt"
      autoLock TRUE
    }
    DEF arrow_shape Shape {
      geometry Cylinder {
        height 0.2
        radius 0.005
      }
    }
  ]
  immersionProperties [
    ImmersionProperties {
      fluidName "fluid"
      referenceArea "xyz-projection"
      dragForceCoefficients 1.5 1.5 1.5
    }
  ]
  boundingObject USE arrow_shape
  physics Physics {
    density 500
  }
}
DEF arm Robot {
  translation 0 0 0.15
  rotation 1 0 0 1.5707
  children [
    Transform {
      translation 0.07 0.15 0
      children [
        HingeJoint {
          jointParameters HingeJointParameters {
            axis -1 0 0
          }
          device [
            PositionSensor {
              name "arm angle sensor"
            }
            RotationalMotor {
              name "arm motor"
              maxVelocity 100
            }
          ]
          endPoint Solid {
            translation 0 0.05 0
            rotation -1 0 0 0
            children [
              Connector {
                translation 0 0.05 0
                rotation -0.9999999999999999 0 0 1.5707
                model "arm_cnt"
                isLocked TRUE
                autoLock TRUE
              }
              Shape {
                appearance VarnishedPine {
                }
                geometry Cylinder {
                  height 0.1
                  radius 0.015
                }
              }
            ]
            boundingObject Shape {
              appearance Appearance {
                texture ImageTexture {
                  url [
                    "textures/wood.jpg"
                  ]
                }
              }
              geometry Cylinder {
                height 0.1
                radius 0.015
              }
            }
            physics Physics {
              density 100
            }
          }
        }
      ]
    }
    DEF BaseLink_Shape Shape {
      appearance Appearance {
        texture ImageTexture {
          url [
            "textures/wood.jpg"
          ]
        }
      }
      geometry Cylinder {
        height 0.3
        radius 0.05
      }
    }
  ]
  boundingObject USE BaseLink_Shape
  physics Physics {
  }
  controller "my_controller"
  controllerArgs [
    ""
  ]
}
SolidPipe {
  translation 0.13 1.52 -5.00904e-05
  rotation 1 0 0 1.5707
  height 0.2
  radius 0.1
  thickness 0.01
}
Fluid {
  translation 0 0.76 0
  density 1.29
  viscosity 1.5e-05
  boundingObject Box {
  }
}
